Workbook

Sheet 00_總覽
A1: 拾壹間發包金額完整核對（2026-07-12）
A2: 指標 | B2: 數值 | C2: 說明
A3: 來源文件數 | B3: =COUNTA('01_逐份核對'!A2:A94) | C3: 應為93
A4: 計入筆數 | B4: =COUNTIF('01_逐份核對'!M2:M94,"計入") | C4: 固定金額列
A5: 原文件口徑總額 | B5: =SUM('01_逐份核對'!N2:N94) | C5: 保留明載稅別
A6: 已知稅別換算含稅 | B6: =SUM('01_逐份核對'!O2:O94) | C6: 未稅項目加5%
A7: 待確認文件數 | B7: =COUNTIF('01_逐份核對'!M2:M94,"待確認*") | C7: 不進固定總額
A8: 明載未稅列數 | B8: =COUNTIFS('01_逐份核對'!M2:M94,"計入",'01_逐份核對'!J2:J94,"未稅") | C8: 換算含稅
A9: 稅別未明採列額 | B9: =SUMIFS('01_逐份核對'!K2:K94,'01_逐份核對'!M2:M94,"計入",'01_逐份核對'!J2:J94,"未明") | C9: 若外加5%另增
A10: 先前暫定總額 | B10: 52539974 | C10: 2026-07-12前次回覆
A11: 本次修正差額 | B11: =B5-B10 | C11: 新減舊
A12: 含稅上限（未明皆加5%） | B12: =B6+ROUND(B9*5%,0) | C12: 風險上限
A14: 分類 | B14: 原文件口徑 | C14: 視覺
A15: 其他 | B15: =SUMIFS('01_逐份核對'!N$2:N$94,'01_逐份核對'!C$2:C$94,A15) | C15: =REPT("█",ROUND(B15/MAX(B$15:B$20)*20,0))
A16: 室內／公設／景觀 | B16: =SUMIFS('01_逐份核對'!N$2:N$94,'01_逐份核對'!C$2:C$94,A16) | C16: =REPT("█",ROUND(B16/MAX(B$15:B$20)*20,0))
A17: 機電／水電／弱電 | B17: =SUMIFS('01_逐份核對'!N$2:N$94,'01_逐份核對'!C$2:C$94,A17) | C17: =REPT("█",ROUND(B17/MAX(B$15:B$20)*20,0))
A18: 結構／泥作／防水 | B18: =SUMIFS('01_逐份核對'!N$2:N$94,'01_逐份核對'!C$2:C$94,A18) | C18: =REPT("█",ROUND(B18/MAX(B$15:B$20)*20,0))
A19: 衛浴／廚具／建材 | B19: =SUMIFS('01_逐份核對'!N$2:N$94,'01_逐份核對'!C$2:C$94,A19) | C19: =REPT("█",ROUND(B19/MAX(B$15:B$20)*20,0))
A20: 門窗／玻璃／鋁作 | B20: =SUMIFS('01_逐份核對'!N$2:N$94,'01_逐份核對'!C$2:C$94,A20) | C20: =REPT("█",ROUND(B20/MAX(B$15:B$20)*20,0))

Sheet 01_逐份核對
A1: 來源文件 | B1: 廠商 | C1: 分類 | D1: 工項／版本 | E1: 文件日期 | F1: 明載未稅 | G1: 明載稅額 | H1: 明載總額 | I1: 稅別原文 | J1: 稅別分類 | K1: 採列額 | L1: 換算含稅 | M1: 狀態 | N1: 有效原額 | O1: 有效含稅 | P1: 信心 | Q1: 版本群組 | R1: 採列依據 | S1: 證據 | T1: 備註
A2: 0921向上建設機械車位合約.docx | B2: 俐麒企業有限公司 | C2: 機電／水電／弱電 | D2: 機械停車設備（8個三層橫移車位） | E2: 2023-09-21 | F2: 1400000 | G2: 70000 | H2: 1470000 | I2: 含稅 | J2: 含稅 | K2: 1470000 | L2: =IF(K2="","",IF(J2="未稅",ROUND(K2*1.05,0),K2)) | M2: 計入 | N2: =IF(M2="計入",K2,0) | O2: =IF(M2="計入",L2,0) | P2: high | Q2: 機械車位-俐麒 | R2: 合約報價單合計（含5%稅） | S2: 「稅金5％ 70,000；合計 1,470,000；總價新台幣壹佰肆拾柒萬元整」 | T2: 兩項備註加購未併入合約合計。
A3: 20230424 TOTO衛浴.md | B3: 建信自動化有限公司／晉展股份有限公司 | C3: 衛浴／廚具／建材 | D3: TOTO衛浴設備及安裝 | F3: 1533510 | G3: 76676 | H3: 1610186 | I3: 含稅 | J3: 含稅 | L3: =IF(K3="","",IF(J3="未稅",ROUND(K3*1.05,0),K3)) | M3: 排除／重複或替代 | N3: =IF(M3="計入",K3,0) | O3: =IF(M3="計入",L3,0) | P3: high | Q3: TOTO衛浴-累計版本 | R3: 依使用者決策：舊TOTO版不計入 | S3: 「實收1,577,000元含稅價；小計1,533,510；稅額76,676；總計1,610,186」 | T3: 舊版；TOTO僅保留2025-12-22累計版。日期未見明載。
A4: 20230613 地質鑽探.md | B4: 川島地質工程 | C4: 結構／泥作／防水 | D4: 地質鑽探（2孔×6m） | E4: 2023-06-13 | F4: 35000 | G4: 1750 | H4: 36750 | I4: 含稅 | J4: 含稅 | K4: 36750 | L4: =IF(K4="","",IF(J4="未稅",ROUND(K4*1.05,0),K4)) | M4: 計入 | N4: =IF(M4="計入",K4,0) | O4: =IF(M4="計入",L4,0) | P4: high | Q4: 地質鑽探-川島 | R4: 工程總價／合計 | S4: 「小計35000；營業稅1750；合計36750；工程總價新臺幣叁萬陸仟柒佰伍拾元整」 | T4: 日期原文112/6/13。
A5: 20231212 YKK 鋁門窗.md | B5: 新悅有限公司 | C5: 門窗／玻璃／鋁作 | D5: YKK鋁門窗 | E5: 2023-12-12 | F5: 2378781 | G5: 118939 | H5: 2497720 | I5: 含稅 | J5: 含稅 | K5: 2497720 | L5: =IF(K5="","",IF(J5="未稅",ROUND(K5*1.05,0),K5)) | M5: 計入 | N5: =IF(M5="計入",K5,0) | O5: =IF(M5="計入",L5,0) | P5: high | Q5: YKK鋁門窗-新悅 | R5: 總計（含稅、實價） | S5: 「合計2,378,781（未稅）；5%稅金118,939；總計2,497,720（含稅、實價）」 | T5: 日期原文112年12月12日。
A6: 20231226 TOTO衛浴.md | B6: 建信自動化有限公司／晉展股份有限公司 | C6: 衛浴／廚具／建材 | D6: TOTO衛浴設備及安裝 | E6: 2023-12-26 | F6: 1848110 | G6: 92406 | H6: 1940516 | I6: 含稅 | J6: 含稅 | L6: =IF(K6="","",IF(J6="未稅",ROUND(K6*1.05,0),K6)) | M6: 排除／重複或替代 | N6: =IF(M6="計入",K6,0) | O6: =IF(M6="計入",L6,0) | P6: high | Q6: TOTO衛浴-累計版本 | R6: 依使用者決策：舊TOTO版不計入 | S6: 「實收1,907,330元含稅價；小計1,848,110；稅額92,406；總計1,940,516」 | T6: 舊版；TOTO僅保留2025-12-22累計版。
A7: 20240326 國璽寶 磁磚.md | B7: 國璽寶建材／昌盛磁磚 | C7: 衛浴／廚具／建材 | D7: 磁磚材料單價表 | E7: 2024-03-26 | I7: 未稅 | J7: 未稅 | L7: =IF(K7="","",IF(J7="未稅",ROUND(K7*1.05,0),K7)) | M7: 排除／非計價或未採用 | N7: =IF(M7="計入",K7,0) | O7: =IF(M7="計入",L7,0) | P7: high | Q7: 國璽寶磁磚單價 | R7: 僅單價表，無數量及固定總額 | S7: 備註「以上報價均不含5%營業稅」；各品項僅列單價 | T7: 無固定總額，不計入發包總額。
A8: 20240506 鎖庫 智能衣架.md | B8: 鎖庫智能 | C8: 其他 | D8: 智能升降曬衣架 | E8: 2024-05-06 | F8: 10620 | H8: 10620 | I8: 未稅 | J8: 未稅 | K8: 10620 | L8: =IF(K8="","",IF(J8="未稅",ROUND(K8*1.05,0),K8)) | M8: 計入 | N8: =IF(M8="計入",K8,0) | O8: =IF(M8="計入",L8,0) | P8: high | Q8: 鎖庫-智能衣架 | R8: 明載總價未稅 | S8: 「台熱牌TCM-210BS，數量1，建商優惠價10620；總價未稅10620」 | T8: 營業稅未計。
A9: 20240506 鎖庫 電子門鎖.md | B9: 鎖庫智能 | C9: 門窗／玻璃／鋁作 | D9: 電子門鎖選型 | E9: 2024-03-20 | I9: 未稅 | J9: 未稅 | L9: =IF(K9="","",IF(J9="未稅",ROUND(K9*1.05,0),K9)) | M9: 排除／非計價或未採用 | N9: =IF(M9="計入",K9,0) | O9: =IF(M9="計入",L9,0) | P9: high | Q9: 鎖庫-電子門鎖方案 | R9: 兩方案且總價欄空白，未選型 | S9: 「飛利浦7300優惠價13,500；耶魯7216A優惠價16,000；總價未稅欄空白」 | T9: 待確認選型與數量；檔名日期與明載報價日不同，以原文2024/3/20為準。
A10: 20240507 固多多.md | B10: 將成實業社 | C10: 其他 | D10: 固多多窗角結構壁面防裂元件 | F10: 112140 | H10: 112140 | I10: 未稅 | J10: 未稅 | K10: 112140 | L10: =IF(K10="","",IF(J10="未稅",ROUND(K10*1.05,0),K10)) | M10: 計入 | N10: =IF(M10="計入",K10,0) | O10: =IF(M10="計入",L10,0) | P10: high | Q10: 固多多-窗角防裂 | R10: 報價總計未稅 | S10: 「267枚×420元；總價112,140元；報價總計新台幣112,140元整（未稅）」 | T10: OCR廠商字樣略糊；金額可由267×420交叉核對。
A11: 20240515 Derek 白框淋浴拉門.md | B11: 隆昌窯業（Derek） | C11: 門窗／玻璃／鋁作 | D11: 淋浴拉門白框／無框方案 | F11: 340200 | G11: 17010 | H11: 357210 | I11: 含稅 | J11: 含稅 | L11: =IF(K11="","",IF(J11="未稅",ROUND(K11*1.05,0),K11)) | M11: 排除／重複或替代 | N11: =IF(M11="計入",K11,0) | O11: =IF(M11="計入",L11,0) | P11: high | Q11: 淋浴拉門-競合版本 | R11: 依使用者決策：Derek只保留黑框版 | S11: 「未稅總價340,200；5%營業稅17,010；含稅總價357,210」 | T11: 同日替代方案，未保留。
A12: 20240515 Derek黑框淋浴拉門.md | B12: 隆昌窯業（Derek） | C12: 門窗／玻璃／鋁作 | D12: 黑框淋浴拉門 | F12: 252000 | G12: 12600 | H12: 264600 | I12: 含稅 | J12: 含稅 | K12: 264600 | L12: =IF(K12="","",IF(J12="未稅",ROUND(K12*1.05,0),K12)) | M12: 計入 | N12: =IF(M12="計入",K12,0) | O12: =IF(M12="計入",L12,0) | P12: high | Q12: 淋浴拉門-競合版本 | R12: 使用者指定只保留黑框含稅總價 | S12: 「未稅總價252,000；5%營業稅12,600；含稅總價264,600」 | T12: 報價日原文未辨識。
A13: 20240620 協力建材行.md | B13: 協力建材有限公司／金協和建材有限公司 | C13: 衛浴／廚具／建材 | D13: 紅磚、砂、水泥、黏著劑等材料單價表 | E13: 2024-06-20 | I13: 未稅 | J13: 未稅 | L13: =IF(K13="","",IF(J13="未稅",ROUND(K13*1.05,0),K13)) | M13: 排除／非計價或未採用 | N13: =IF(M13="計入",K13,0) | O13: =IF(M13="計入",L13,0) | P13: high | Q13: 協力建材-材料單價版本 | R13: 依使用者決策：只保留2024-08-12版 | S13: 「以上產品單價均為未稅價」；無合計 | T13: 舊單價版，無固定總額。
A14: 20240620 塑豐 玄關門、房間門、浴室門、消防門.md | B14: 塑豐實業股份有限公司 | C14: 門窗／玻璃／鋁作 | D14: 玄關門、房間／浴室門、消防門（三項） | E14: 2024-06-20 | F14: 1476190 | G14: 73810 | H14: 1550000 | I14: 含稅 | J14: 含稅 | L14: =IF(K14="","",IF(J14="未稅",ROUND(K14*1.05,0),K14)) | M14: 排除／非計價或未採用 | N14: =IF(M14="計入",K14,0) | O14: =IF(M14="計入",L14,0) | P14: medium | Q14: 塑豐門-最終累計 | R14: 同內容由完整累計檔統一承接；本檔不重複計入 | S14: 原文明載三組：764,453、253,617、531,930；其中第一組表內小計728,050、稅36,403 | T14: 與無空格同名檔內容重複；避免重複計入。第一組檔首另見總計764,453。
A15: 20240620 塑豐玄關門、房間門、浴室門、消防門.md | B15: 塑豐實業股份有限公司 | C15: 門窗／玻璃／鋁作 | D15: 塑豐門原三項＋房間門改先立 | E15: 2024-10-16 | F15: 1757702 | G15: 87886 | H15: 1845588 | I15: 含稅 | J15: 含稅 | K15: 1845588 | L15: =IF(K15="","",IF(J15="未稅",ROUND(K15*1.05,0),K15)) | M15: 計入 | N15: =IF(M15="計入",K15,0) | O15: =IF(M15="計入",L15,0) | P15: high | Q15: 塑豐門-最終累計 | R15: 使用者指定最終合計；原三項1,550,000＋改先立295,588 | S15: 原文含764,453、531,930、253,617及113.10.16改先立295,588；加總1,845,588 | T15: doc_date採檔內最新版本日；chosen_amount為使用者已裁定的累計額。
A16: 20240703 太子種苗 _更新_.md | B16: 太子種苗園 | C16: 室內／公設／景觀 | D16: 景觀植栽／支撐工程 | E16: 2025-07-03 | F16: 132640 | G16: 6632 | H16: 139272 | I16: 含稅 | J16: 含稅 | K16: 139272 | L16: =IF(K16="","",IF(J16="未稅",ROUND(K16*1.05,0),K16)) | M16: 計入 | N16: =IF(M16="計入",K16,0) | O16: =IF(M16="計入",L16,0) | P16: medium | Q16: 太子種苗-景觀更新 | R16: 合計加稅後總計 | S16: 「合計132,640；稅金6,632；總計139,272」 | T16: 原文明載2025年7月3日，與檔名20240703不一致，待確認年份。
A17: 20240719 立瑄 淋浴拉門.md | B17: 立瑄有限公司 | C17: 門窗／玻璃／鋁作 | D17: 無框外開淋浴拉門 | F17: 198000 | G17: 9900 | H17: 207900 | I17: 含稅 | J17: 含稅 | L17: =IF(K17="","",IF(J17="未稅",ROUND(K17*1.05,0),K17)) | M17: 排除／非計價或未採用 | N17: =IF(M17="計入",K17,0) | O17: =IF(M17="計入",L17,0) | P17: high | Q17: 淋浴拉門-競合版本 | R17: 與使用者指定保留的Derek黑框方案競合，不另計 | S17: 「小計198000；營業稅9900；合計207900」 | T17: 報價日未見明載；作為競價方案排除。
A18: 20240726 塑豐 金屬格柵.md | B18: 塑豐實業股份有限公司 | C18: 門窗／玻璃／鋁作 | D18: 鋁格柵方案A／B | E18: 2024-07-26 | I18: 含稅 | J18: 含稅 | L18: =IF(K18="","",IF(J18="未稅",ROUND(K18*1.05,0),K18)) | M18: 排除／重複或替代 | N18: =IF(M18="計入",K18,0) | O18: =IF(M18="計入",L18,0) | P18: high | Q18: 塑豐格柵-版本 | R18: 同日兩方案且後有2024-11-26更新版 | S18: 方案A小計573,678、稅28,684、總計602,362；方案B小計461,093、稅23,055、總計484,148 | T18: 替代方案且已被2024-11-26更新版取代。
A19: 20240730 國璽寶 車道磚.md | B19: 國璽寶建材／昌盛磁磚 | C19: 其他 | D19: 車道磚材料單價表 | E19: 2024-07-30 | I19: 未稅 | J19: 未稅 | L19: =IF(K19="","",IF(J19="未稅",ROUND(K19*1.05,0),K19)) | M19: 排除／非計價或未採用 | N19: =IF(M19="計入",K19,0) | O19: =IF(M19="計入",L19,0) | P19: high | Q19: 國璽寶車道磚單價 | R19: 僅單價表，無數量及固定總額 | S19: GR-1004、GR-1007均僅列單價6.5元；備註不含5%營業稅 | T19: 無固定總額，不計入。
A20: 20240730 錦祥工程行 _浴室天花板_.md | B20: 錦祥工程行 | C20: 室內／公設／景觀 | D20: 浴室矽酸鈣天花板及搬運 | F20: 115400 | G20: 5770 | H20: 121170 | I20: 含稅 | J20: 含稅 | K20: 121170 | L20: =IF(K20="","",IF(J20="未稅",ROUND(K20*1.05,0),K20)) | M20: 計入 | N20: =IF(M20="計入",K20,0) | O20: =IF(M20="計入",L20,0) | P20: high | Q20: 錦祥-浴室天花板 | R20: 合計總金額 | S20: 「銷售金額合計115400；營業稅5770；合計總金額121170」 | T20: 報價日未見明載。
A21: 20240802 宏交 弱電系統.md | B21: 宏交電話器材有限公司 | C21: 機電／水電／弱電 | D21: 弱電系統（監視、門禁、對講、車道） | E21: 2024-08-02 | F21: 304762 | G21: 15238 | H21: 320000 | I21: 含稅 | J21: 含稅 | K21: 320000 | L21: =IF(K21="","",IF(J21="未稅",ROUND(K21*1.05,0),K21)) | M21: 計入 | N21: =IF(M21="計入",K21,0) | O21: =IF(M21="計入",L21,0) | P21: high | Q21: 宏交-弱電系統 | R21: 合約總金額／議價後報價總計 | S21: 合約「參拾貳萬元整（320,000元含稅金）」；報價合計304,762、稅15,238、總計320,000 | T21: 報價單號113080203；合約編號填doc_number。
A22: 20240809 塑豐 玻璃欄桿.md | B22: 塑豐實業股份有限公司 | C22: 其他 | D22: 玻璃欄杆 | E22: 2024-08-09 | F22: 570882 | G22: 28544 | H22: 599426 | I22: 含稅 | J22: 含稅 | L22: =IF(K22="","",IF(J22="未稅",ROUND(K22*1.05,0),K22)) | M22: 排除／非計價或未採用 | N22: =IF(M22="計入",K22,0) | O22: =IF(M22="計入",L22,0) | P22: high | Q22: 玻璃欄杆-競合版本 | R22: 與順靖玻璃欄杆最終版競合，不計入 | S22: 「合計570,882；稅金28,544；總計599,426」 | T22: 使用者指定順靖玻璃僅保留版次3。
A23: 20240812 協力建材行.md | B23: 協力建材有限公司／金協和建材有限公司 | C23: 衛浴／廚具／建材 | D23: 紅磚、砂、水泥、黏著劑等材料單價表 | E23: 2024-08-12 | I23: 未稅 | J23: 未稅 | L23: =IF(K23="","",IF(J23="未稅",ROUND(K23*1.05,0),K23)) | M23: 待確認／無固定總額 | N23: =IF(M23="計入",K23,0) | O23: =IF(M23="計入",L23,0) | P23: high | Q23: 協力建材-材料單價版本 | R23: 最新版單價表，無固定總額 | S23: 「以上產品單價均為未稅價」；依實際進貨數量請款 | T23: 保留為單價契約；沒有數量與固定總額，不納入固定發包總額。
A24: 20240819 順靖 樓梯扶手.md | B24: 順靖企業有限公司 | C24: 其他 | D24: 樓梯扶手 | E24: 2024-08-19 | F24: 198500 | H24: 198500 | I24: 未稅 | J24: 未稅 | K24: 198500 | L24: =IF(K24="","",IF(J24="未稅",ROUND(K24*1.05,0),K24)) | M24: 計入 | N24: =IF(M24="計入",K24,0) | O24: =IF(M24="計入",L24,0) | P24: high | Q24: 順靖-樓梯扶手獨立 | R24: 獨立樓梯扶手小計（使用者指示若獨立則保留） | S24: 「77米 小計198,500」；「未含5%營業稅」 | T24: 屬獨立工項；完工依實際米數實做實算。
A25: 20240820 富日東 塗料.md | B25: 富日東建材／富千代開發 | C25: 室內／公設／景觀 | D25: SKK單彩系波浪紋理塗料工程 | E25: 2024-08-20 | F25: 854192 | I25: 未稅 | J25: 未稅 | K25: 854192 | L25: =IF(K25="","",IF(J25="未稅",ROUND(K25*1.05,0),K25)) | M25: 計入 | N25: =IF(M25="計入",K25,0) | O25: =IF(M25="計入",L25,0) | P25: medium | Q25: 富日東-外牆塗料 | R25: 唯一主項各項小計；總計欄空白 | S25: 「928.47㎡×920，各項小計854,192」；「總計：新台幣 元」空白；不含5%營業稅 | T25: chosen_amount採唯一主項明載複價，非總計欄；數量為概算，待圖面後可能增減。
A26: 20240910 順靖 玻璃欄杆(透明).md | B26: 順靖企業有限公司 | C26: 門窗／玻璃／鋁作 | D26: 不鏽鋼透明玻璃陽台欄杆 | E26: 2024-09-10 | F26: 778797 | H26: 778797 | I26: 未稅 | J26: 未稅 | L26: =IF(K26="","",IF(J26="未稅",ROUND(K26*1.05,0),K26)) | M26: 排除／重複或替代 | N26: =IF(M26="計入",K26,0) | O26: =IF(M26="計入",L26,0) | P26: high | Q26: 順靖玻璃欄杆-版本 | R26: 版次2，被版次3取代 | S26: 「報價版次2；33座；小計778,797；未含5%營業稅」 | T26: 舊版。
A27: 20241004 順靖 玻璃欄杆_透明_木紋握桿_ 議價.md | B27: 順靖企業有限公司 | C27: 門窗／玻璃／鋁作 | D27: 不鏽鋼透明玻璃陽台欄杆＋木紋握桿 | E27: 2024-10-04 | F27: 692293 | H27: 692293 | I27: 未稅 | J27: 未稅 | K27: 690000 | L27: =IF(K27="","",IF(J27="未稅",ROUND(K27*1.05,0),K27)) | M27: 計入 | N27: =IF(M27="計入",K27,0) | O27: =IF(M27="計入",L27,0) | P27: high | Q27: 順靖玻璃欄杆-版本 | R27: 使用者指定版次3議價後690,000未稅 | S27: 「報價版次3；小計692,293；備註10%議價 $690,000（未稅）」 | T27: 以議價後金額優先。
A28: 20241009 安翊 滴水條.md | B28: 安翊企業股份有限公司 | C28: 其他 | D28: 烤漆滴水條安裝 | E28: 2024-10-09 | F28: 197500 | G28: 9875 | H28: 207375 | I28: 含稅 | J28: 含稅 | K28: 207375 | L28: =IF(K28="","",IF(J28="未稅",ROUND(K28*1.05,0),K28)) | M28: 計入 | N28: =IF(M28="計入",K28,0) | O28: =IF(M28="計入",L28,0) | P28: high | Q28: 安翊-滴水條 | R28: 總金額 | S28: 「報價淨額197,500；稅額9,875；總金額207,375」 | T28: 依實作數量計價。
A29: 20241016 塑豐 房間門改先立.md | B29: 塑豐實業股份有限公司 | C29: 門窗／玻璃／鋁作 | D29: 南亞房間門改先立 | E29: 2024-10-16 | F29: 281512 | G29: 14076 | H29: 295588 | I29: 含稅 | J29: 含稅 | L29: =IF(K29="","",IF(J29="未稅",ROUND(K29*1.05,0),K29)) | M29: 排除／非計價或未採用 | N29: =IF(M29="計入",K29,0) | O29: =IF(M29="計入",L29,0) | P29: high | Q29: 塑豐門-最終累計 | R29: 已併入塑豐門最終累計1,845,588，不重複計入 | S29: 「小計281,512；稅金14,076；總計295,588」 | T29: 獨立檔為累計檔中的組成項。
A30: 20241017 塑豐 防颱百葉窗.md | B30: 塑豐實業股份有限公司 | C30: 門窗／玻璃／鋁作 | D30: 防颱百葉窗追加 | E30: 2024-10-17 | F30: 23216 | G30: 1161 | H30: 24377 | I30: 含稅 | J30: 含稅 | K30: 24377 | L30: =IF(K30="","",IF(J30="未稅",ROUND(K30*1.05,0),K30)) | M30: 計入 | N30: =IF(M30="計入",K30,0) | O30: =IF(M30="計入",L30,0) | P30: high | Q30: 塑豐-防颱百葉窗追加 | R30: 總計／中文大寫總金額 | S30: 「合計23,216；營業稅1,161；總計24,377；總金額貳萬肆仟參佰柒拾柒元整」 | T30: 追加獨立工項。
A31: 20241126 塑豐 格柵.md | B31: 塑豐實業股份有限公司 | C31: 門窗／玻璃／鋁作 | D31: 鋁格柵更新版 | E31: 2024-11-26 | F31: 1147854 | G31: 57393 | H31: 1205247 | I31: 含稅 | J31: 含稅 | K31: 1205247 | L31: =IF(K31="","",IF(J31="未稅",ROUND(K31*1.05,0),K31)) | M31: 計入 | N31: =IF(M31="計入",K31,0) | O31: =IF(M31="計入",L31,0) | P31: medium | Q31: 塑豐格柵-版本 | R31: 小計加明載稅金（總額由兩者可核算） | S31: 「小計1,147,854；稅金57,393」；合計核算1,205,247 | T31: 原文未擷取到「總計」標籤，chosen_amount為明載小計＋稅金；待確認影像是否有總計。
A32: 20241211 塑豐 鍍鋅烤漆門 換手把.md | B32: 塑豐實業股份有限公司 | C32: 門窗／玻璃／鋁作 | D32: 鍍鋅烤漆門換手把續更 | E32: 2024-12-11 | F32: 75238 | I32: 未明載 | J32: 未明 | L32: =IF(K32="","",IF(J32="未稅",ROUND(K32*1.05,0),K32)) | M32: 排除／非計價或未採用 | N32: =IF(M32="計入",K32,0) | O32: =IF(M32="計入",L32,0) | P32: medium | Q32: 塑豐門-最終累計 | R32: 使用者指定塑豐門最終僅原三項＋改先立；本續更不另加 | S32: 「小計75,238」；未見稅金或總計 | T32: 是否為原玄關門內部規格更新未明；依使用者最終裁定不另計。
A33: 20250212 智慧城植草磚、透水磚.md | B33: 智慧城企業有限公司 | C33: 衛浴／廚具／建材 | D33: 植草磚、透水磚及工資 | E33: 2025-02-12 | F33: 56731 | G33: 2837 | H33: 59568 | I33: 含稅 | J33: 含稅 | K33: 59568 | L33: =IF(K33="","",IF(J33="未稅",ROUND(K33*1.05,0),K33)) | M33: 計入 | N33: =IF(M33="計入",K33,0) | O33: =IF(M33="計入",L33,0) | P33: high | Q33: 智慧城-植草透水磚 | R33: 初估總計 | S33: 明細未稅合計56,731；稅金2,837；初估總計59,568 | T33: 數量金額為初估，完工實做實算。
A34: 20250220 塑豐 格柵 追加.md | B34: 塑豐實業股份有限公司 | C34: 門窗／玻璃／鋁作 | D34: 鋁格柵追加 | E34: 2025-02-20 | F34: 60918 | I34: 未明載 | J34: 未明 | K34: 60918 | L34: =IF(K34="","",IF(J34="未稅",ROUND(K34*1.05,0),K34)) | M34: 計入 | N34: =IF(M34="計入",K34,0) | O34: =IF(M34="計入",L34,0) | P34: medium | Q34: 塑豐格柵-追加 | R34: 明載追加報價小計 | S34: 「小計60,918」；未見稅金或總計 | T34: 待確認60,918是否未稅及是否另加5%營業稅。
A35: 20250220 裕苗表內管報價.md | B35: 裕苗天然氣股份有限公司 | C35: 機電／水電／弱電 | D35: 天然氣表內管裝置工程 | E35: 2025-02-20 | F35: 377065 | G35: 18855 | H35: 395920 | I35: 含稅 | J35: 含稅 | K35: 395920 | L35: =IF(K35="","",IF(J35="未稅",ROUND(K35*1.05,0),K35)) | M35: 計入 | N35: =IF(M35="計入",K35,0) | O35: =IF(M35="計入",L35,0) | P35: high | Q35: 裕苗-天然氣表內管 | R35: 總計 | S35: 「表內管合計377,065；營業稅18,855；總計395,920」 | T35: 申請單編號051130070-051130080（共11戶）。
A36: 20250506 楠弘柏加 _廚房Grohe伸縮龍頭_.md | B36: 柏加企業股份有限公司 | C36: 衛浴／廚具／建材 | D36: Grohe廚房伸縮龍頭 | E36: 2025-05-06 | H36: 96800 | I36: 含稅 | J36: 含稅 | L36: =IF(K36="","",IF(J36="未稅",ROUND(K36*1.05,0),K36)) | M36: 排除／重複或替代 | N36: =IF(M36="計入",K36,0) | O36: =IF(M36="計入",L36,0) | P36: high | Q36: 柏加-Grohe龍頭版本 | R36: 後續2025-05-08買賣合約／5-09報價取代 | S36: 「含稅金額小計96,800；合計96,800」 | T36: 與後續合約同報價單號；不重複計入。
A37: 20250508 楠弘柏加 合約.md | B37: 柏加企業股份有限公司 | C37: 其他 | D37: Grohe廚房伸縮龍頭＋安裝 | E37: 2025-05-09 | H37: 111650 | I37: 含稅 | J37: 含稅 | K37: 111650 | L37: =IF(K37="","",IF(J37="未稅",ROUND(K37*1.05,0),K37)) | M37: 計入 | N37: =IF(M37="計入",K37,0) | O37: =IF(M37="計入",L37,0) | P37: high | Q37: 柏加-Grohe龍頭版本 | R37: 合約附件報價及付款分期總和 | S37: 附件含稅金額96,800＋安裝14,850；付款20% 22,330＋75% 83,738＋5% 5,582＝111,650 | T37: 主檔名5/8；附件報價日期25/05/09，doc_date採明載附件日期。稅額未分列。
A38: 20250514 TOTO 衛浴更新.md | B38: 建信自動化有限公司／晉展股份有限公司 | C38: 衛浴／廚具／建材 | D38: TOTO衛浴設備及安裝 | E38: 2024-08-26 | F38: 1952298 | G38: 97615 | H38: 2049913 | I38: 含稅 | J38: 含稅 | L38: =IF(K38="","",IF(J38="未稅",ROUND(K38*1.05,0),K38)) | M38: 排除／重複或替代 | N38: =IF(M38="計入",K38,0) | O38: =IF(M38="計入",L38,0) | P38: high | Q38: TOTO衛浴-累計版本 | R38: 依使用者決策：舊TOTO版不計入 | S38: 「小計1,952,298；稅額97,615；總計2,049,913；報價日期113年8月26日」 | T38: 舊版；TOTO僅保留2025-12-22累計版。檔名20250514與原文明載日期不一致。
A39: 20250807 順靖 玻璃修復.md | B39: 順靖企業有限公司 | C39: 其他 | D39: 報價版次1／單一版 | E39: 2025-08-07 | F39: 8000 | H39: 8000 | I39: 未稅 | J39: 未稅 | K39: 8000 | L39: =IF(K39="","",IF(J39="未稅",ROUND(K39*1.05,0),K39)) | M39: 計入 | N39: =IF(M39="計入",K39,0) | O39: =IF(M39="計入",L39,0) | P39: high | Q39: 報價版次1／單一版 | R39: 小計；明載未含5%營業稅 | S39: 原文L11、L25、L27、L33：版次1，玻璃修復小計8,000，未含5%營業稅。 | T39: 固定一式報價，非同廠商舊版替代鏈。
A40: 20250922宇勝工程行-水電報價單.md | B40: 宇勝工程行 | C40: 機電／水電／弱電 | D40: 議價定案版 | E40: 2025-09-17 | F40: 2542050 | G40: 127103 | H40: 2600000 | I40: 含稅 | J40: 含稅 | K40: 2600000 | L40: =IF(K40="","",IF(J40="未稅",ROUND(K40*1.05,0),K40)) | M40: 計入 | N40: =IF(M40="計入",K40,0) | O40: =IF(M40="計入",L40,0) | P40: high | Q40: 議價定案版 | R40: 表列原總計2,669,153；另明載議價後含稅2,600,000（含8、9月點工），以議價額為準 | S40: 原文L7表格末段：小計2,542,050、稅金127,103、總計2,669,153；同段註記『議價為含稅2600000含8月、9月點工』。 | T40: 依使用者決策，宇勝2,600,000含稅與信興10,500,000含稅分開並列，不互相取代。
...

Sheet 02_計入明細
A1: 來源文件 | B1: 廠商 | C1: 分類 | D1: 採列額 | E1: 稅別 | F1: 換算含稅 | G1: 狀態 | H1: 採列／排除依據 | I1: 證據
A2: 0921向上建設機械車位合約.docx | B2: 俐麒企業有限公司 | C2: 機電／水電／弱電 | D2: 1470000 | E2: 含稅 | F2: =IF(D2="","",IF(E2="未稅",ROUND(D2*1.05,0),D2)) | G2: 計入 | H2: 合約報價單合計（含5%稅） | I2: 「稅金5％ 70,000；合計 1,470,000；總價新台幣壹佰肆拾柒萬元整」
A3: 20230613 地質鑽探.md | B3: 川島地質工程 | C3: 結構／泥作／防水 | D3: 36750 | E3: 含稅 | F3: =IF(D3="","",IF(E3="未稅",ROUND(D3*1.05,0),D3)) | G3: 計入 | H3: 工程總價／合計 | I3: 「小計35000；營業稅1750；合計36750；工程總價新臺幣叁萬陸仟柒佰伍拾元整」
A4: 20231212 YKK 鋁門窗.md | B4: 新悅有限公司 | C4: 門窗／玻璃／鋁作 | D4: 2497720 | E4: 含稅 | F4: =IF(D4="","",IF(E4="未稅",ROUND(D4*1.05,0),D4)) | G4: 計入 | H4: 總計（含稅、實價） | I4: 「合計2,378,781（未稅）；5%稅金118,939；總計2,497,720（含稅、實價）」
A5: 20240506 鎖庫 智能衣架.md | B5: 鎖庫智能 | C5: 其他 | D5: 10620 | E5: 未稅 | F5: =IF(D5="","",IF(E5="未稅",ROUND(D5*1.05,0),D5)) | G5: 計入 | H5: 明載總價未稅 | I5: 「台熱牌TCM-210BS，數量1，建商優惠價10620；總價未稅10620」
A6: 20240507 固多多.md | B6: 將成實業社 | C6: 其他 | D6: 112140 | E6: 未稅 | F6: =IF(D6="","",IF(E6="未稅",ROUND(D6*1.05,0),D6)) | G6: 計入 | H6: 報價總計未稅 | I6: 「267枚×420元；總價112,140元；報價總計新台幣112,140元整（未稅）」
A7: 20240515 Derek黑框淋浴拉門.md | B7: 隆昌窯業（Derek） | C7: 門窗／玻璃／鋁作 | D7: 264600 | E7: 含稅 | F7: =IF(D7="","",IF(E7="未稅",ROUND(D7*1.05,0),D7)) | G7: 計入 | H7: 使用者指定只保留黑框含稅總價 | I7: 「未稅總價252,000；5%營業稅12,600；含稅總價264,600」
A8: 20240620 塑豐玄關門、房間門、浴室門、消防門.md | B8: 塑豐實業股份有限公司 | C8: 門窗／玻璃／鋁作 | D8: 1845588 | E8: 含稅 | F8: =IF(D8="","",IF(E8="未稅",ROUND(D8*1.05,0),D8)) | G8: 計入 | H8: 使用者指定最終合計；原三項1,550,000＋改先立295,588 | I8: 原文含764,453、531,930、253,617及113.10.16改先立295,588；加總1,845,588
A9: 20240703 太子種苗 _更新_.md | B9: 太子種苗園 | C9: 室內／公設／景觀 | D9: 139272 | E9: 含稅 | F9: =IF(D9="","",IF(E9="未稅",ROUND(D9*1.05,0),D9)) | G9: 計入 | H9: 合計加稅後總計 | I9: 「合計132,640；稅金6,632；總計139,272」
A10: 20240730 錦祥工程行 _浴室天花板_.md | B10: 錦祥工程行 | C10: 室內／公設／景觀 | D10: 121170 | E10: 含稅 | F10: =IF(D10="","",IF(E10="未稅",ROUND(D10*1.05,0),D10)) | G10: 計入 | H10: 合計總金額 | I10: 「銷售金額合計115400；營業稅5770；合計總金額121170」
A11: 20240802 宏交 弱電系統.md | B11: 宏交電話器材有限公司 | C11: 機電／水電／弱電 | D11: 320000 | E11: 含稅 | F11: =IF(D11="","",IF(E11="未稅",ROUND(D11*1.05,0),D11)) | G11: 計入 | H11: 合約總金額／議價後報價總計 | I11: 合約「參拾貳萬元整（320,000元含稅金）」；報價合計304,762、稅15,238、總計320,000
A12: 20240819 順靖 樓梯扶手.md | B12: 順靖企業有限公司 | C12: 其他 | D12: 198500 | E12: 未稅 | F12: =IF(D12="","",IF(E12="未稅",ROUND(D12*1.05,0),D12)) | G12: 計入 | H12: 獨立樓梯扶手小計（使用者指示若獨立則保留） | I12: 「77米 小計198,500」；「未含5%營業稅」
A13: 20240820 富日東 塗料.md | B13: 富日東建材／富千代開發 | C13: 室內／公設／景觀 | D13: 854192 | E13: 未稅 | F13: =IF(D13="","",IF(E13="未稅",ROUND(D13*1.05,0),D13)) | G13: 計入 | H13: 唯一主項各項小計；總計欄空白 | I13: 「928.47㎡×920，各項小計854,192」；「總計：新台幣 元」空白；不含5%營業稅
... A60: 興吉發工程合約 _隔音墊_.md | B60: 興吉發科技建材有限公司 | C60: 結構／泥作／防水 | D60: 419997 | E60: 含稅 | F60: =IF(D60="","",IF(E60="未稅",ROUND(D60*1.05,0),D60)) | G60: 計入 | H60: 正式合約＋報價單No.11307005 | I60: 附件明載未稅總金額約399,998、含稅總金額約419,997；合約付款30%＋70%亦合計419,997。
A61: 合計 | D61: =SUM(D2:D60) | F61: =SUM(F2:F60)

Sheet 03_待確認與排除
A1: 來源文件 | B1: 廠商 | C1: 分類 | D1: 採列額 | E1: 稅別 | F1: 換算含稅 | G1: 狀態 | H1: 採列／排除依據 | I1: 證據
A2: 20230424 TOTO衛浴.md | B2: 建信自動化有限公司／晉展股份有限公司 | C2: 衛浴／廚具／建材 | E2: 含稅 | F2: =IF(D2="","",IF(E2="未稅",ROUND(D2*1.05,0),D2)) | G2: 排除／重複或替代 | H2: 依使用者決策：舊TOTO版不計入 | I2: 「實收1,577,000元含稅價；小計1,533,510；稅額76,676；總計1,610,186」
A3: 20231226 TOTO衛浴.md | B3: 建信自動化有限公司／晉展股份有限公司 | C3: 衛浴／廚具／建材 | E3: 含稅 | F3: =IF(D3="","",IF(E3="未稅",ROUND(D3*1.05,0),D3)) | G3: 排除／重複或替代 | H3: 依使用者決策：舊TOTO版不計入 | I3: 「實收1,907,330元含稅價；小計1,848,110；稅額92,406；總計1,940,516」
A4: 20240326 國璽寶 磁磚.md | B4: 國璽寶建材／昌盛磁磚 | C4: 衛浴／廚具／建材 | E4: 未稅 | F4: =IF(D4="","",IF(E4="未稅",ROUND(D4*1.05,0),D4)) | G4: 排除／非計價或未採用 | H4: 僅單價表，無數量及固定總額 | I4: 備註「以上報價均不含5%營業稅」；各品項僅列單價
A5: 20240506 鎖庫 電子門鎖.md | B5: 鎖庫智能 | C5: 門窗／玻璃／鋁作 | E5: 未稅 | F5: =IF(D5="","",IF(E5="未稅",ROUND(D5*1.05,0),D5)) | G5: 排除／非計價或未採用 | H5: 兩方案且總價欄空白，未選型 | I5: 「飛利浦7300優惠價13,500；耶魯7216A優惠價16,000；總價未稅欄空白」
A6: 20240515 Derek 白框淋浴拉門.md | B6: 隆昌窯業（Derek） | C6: 門窗／玻璃／鋁作 | E6: 含稅 | F6: =IF(D6="","",IF(E6="未稅",ROUND(D6*1.05,0),D6)) | G6: 排除／重複或替代 | H6: 依使用者決策：Derek只保留黑框版 | I6: 「未稅總價340,200；5%營業稅17,010；含稅總價357,210」
A7: 20240620 協力建材行.md | B7: 協力建材有限公司／金協和建材有限公司 | C7: 衛浴／廚具／建材 | E7: 未稅 | F7: =IF(D7="","",IF(E7="未稅",ROUND(D7*1.05,0),D7)) | G7: 排除／非計價或未採用 | H7: 依使用者決策：只保留2024-08-12版 | I7: 「以上產品單價均為未稅價」；無合計
A8: 20240620 塑豐 玄關門、房間門、浴室門、消防門.md | B8: 塑豐實業股份有限公司 | C8: 門窗／玻璃／鋁作 | E8: 含稅 | F8: =IF(D8="","",IF(E8="未稅",ROUND(D8*1.05,0),D8)) | G8: 排除／非計價或未採用 | H8: 同內容由完整累計檔統一承接；本檔不重複計入 | I8: 原文明載三組：764,453、253,617、531,930；其中第一組表內小計728,050、稅36,403
A9: 20240719 立瑄 淋浴拉門.md | B9: 立瑄有限公司 | C9: 門窗／玻璃／鋁作 | E9: 含稅 | F9: =IF(D9="","",IF(E9="未稅",ROUND(D9*1.05,0),D9)) | G9: 排除／非計價或未採用 | H9: 與使用者指定保留的Derek黑框方案競合，不另計 | I9: 「小計198000；營業稅9900；合計207900」
A10: 20240726 塑豐 金屬格柵.md | B10: 塑豐實業股份有限公司 | C10: 門窗／玻璃／鋁作 | E10: 含稅 | F10: =IF(D10="","",IF(E10="未稅",ROUND(D10*1.05,0),D10)) | G10: 排除／重複或替代 | H10: 同日兩方案且後有2024-11-26更新版 | I10: 方案A小計573,678、稅28,684、總計602,362；方案B小計461,093、稅23,055、總計484,148
A11: 20240730 國璽寶 車道磚.md | B11: 國璽寶建材／昌盛磁磚 | C11: 其他 | E11: 未稅 | F11: =IF(D11="","",IF(E11="未稅",ROUND(D11*1.05,0),D11)) | G11: 排除／非計價或未採用 | H11: 僅單價表，無數量及固定總額 | I11: GR-1004、GR-1007均僅列單價6.5元；備註不含5%營業稅
A12: 20240809 塑豐 玻璃欄桿.md | B12: 塑豐實業股份有限公司 | C12: 其他 | E12: 含稅 | F12: =IF(D12="","",IF(E12="未稅",ROUND(D12*1.05,0),D12)) | G12: 排除／非計價或未採用 | H12: 與順靖玻璃欄杆最終版競合，不計入 | I12: 「合計570,882；稅金28,544；總計599,426」
A13: 20240812 協力建材行.md | B13: 協力建材有限公司／金協和建材有限公司 | C13: 衛浴／廚具／建材 | E13: 未稅 | F13: =IF(D13="","",IF(E13="未稅",ROUND(D13*1.05,0),D13)) | G13: 待確認／無固定總額 | H13: 最新版單價表，無固定總額 | I13: 「以上產品單價均為未稅價」；依實際進貨數量請款
... A32: 工程合約-補充協議書.md | B32: 永豐餘工程股份有限公司 | C32: 其他 | E32: 未明 | F32: =IF(D32="","",IF(E32="未稅",ROUND(D32*1.05,0),D32)) | G32: 排除／重複或替代 | H32: 主約付款比例修正版補充協議 | I32: 協議僅變更付款進度，附件仍以24,150,000計算，未新增工程總額。
A33: 暖風機圖面.md | C33: 機電／水電／弱電 | E33: 未明 | F33: =IF(D33="","",IF(E33="未稅",ROUND(D33*1.05,0),D33)) | G33: 排除／非計價或未採用 | H33: 圖面 | I33: 文件僅有圖面影像及1至4編號，未明載報價或總額。
A34: 磁磚廠商預抓費用.jpg | C34: 衛浴／廚具／建材 | E34: 未明 | F34: =IF(D34="","",IF(E34="未稅",ROUND(D34*1.05,0),D34)) | G34: 排除／非計價或未採用 | H34: 預抓費用表 | I34: 圖片12項材料費用表底部明載總計1,036,530；無廠商、日期、稅額或含／未稅文字。
A35: 電梯.md | B35: 崇友實業股份有限公司 | C35: 機電／水電／弱電 | E35: 未明 | F35: =IF(D35="","",IF(E35="未稅",ROUND(D35*1.05,0),D35)) | G35: 排除／重複或替代 | H35: RL-3085升降機選色表 | I35: 文件為電梯規格與選色表，未明載價款。
A36: 合計 | D36: =SUM(D2:D35) | F36: =SUM(F2:F35)

Sheet 04_版本判定
A1: 版本群組 | B1: 保留版本 | C1: 採列金額 | D1: 排除／處理理由
A2: TOTO衛浴 | B2: 20251222TOTO-衛浴報價單回傳.md | C2: 2,079,019 含稅 | D2: 排除所有舊版／累計版
A3: 菊水利諾 | B3: 20251030向上拾壹間新建工程菊水利諾合約回傳.md | C3: 656,775 未稅 | D3: 排除台灣菊水舊合約616,950
A4: 塑豐門類 | B4: 20240620塑豐無空格檔＋20241016改先立 | C4: 1,845,588 含稅 | D4: 原三項1,550,000＋改先立295,588；排除重複有空格檔與續更
A5: 淋浴拉門 | B5: 20240515 Derek黑框淋浴拉門.md | C5: 264,600 含稅 | D5: 排除Derek白框及立瑄競價方案
A6: 玻璃欄杆 | B6: 20241004順靖版次3 | C6: 690,000 未稅 | D6: 排除順靖版次2及塑豐競價方案
A7: 塑豐格柵 | B7: 20241126最新版＋20250220追加 | C7: 1,205,247 含稅＋60,918稅別未明 | D7: 排除20240726方案A/B
A8: 楠弘柏加 | B8: 20250508 楠弘柏加 合約.md | C8: 111,650 含稅 | D8: 同報價單號舊版96,800排除；含安裝費14,850
A9: 長陽鐵捲門 | B9: 20251204回傳版 | C9: 95,000 含稅 | D9: 排除20251121及20251203重複版
A10: 三發圍籬網 | B10: 20260603含運新版 | C10: 44,783 含稅 | D10: 排除20260517不含運舊版
A11: 崇友電梯 | B11: 買賣合約＋安裝承攬 | C11: 889,000＋381,000 含稅 | D11: 標的不同，分開並列
A12: 水電 | B12: 信興＋宇勝 | C12: 10,500,000＋2,600,000 含稅 | D12: 不同發包，分開並列
... A15: 協力建材 | B15: 20240812最新版單價表 | C15: 無固定總額 | D15: 保留單價，不納入固定總額
